Workbook

Sheet Documents_PIA
B2: FIRST COMMUNITY COOPERTIVE DATA INVENTORY
G7: DATA LIFE CYCLE
A8: Doc Ref No. | B8: DOCUMENT/ FILE NAME | C8: DOCUMENT TYPE | D8: DOCUMENT OWNER | E8: BUSINESS PROCESS | F8: DOCUMENT PURPOSE | G8: CONSENT IN COLLECTION | H8: USE | I8: SHARING/ ACCESS BY | J8: STORAGE/REPOSITORY | K8: RETENTION PERIOD | L8: BASIS OF RETENTION | M8: DISPOSAL | N8: DOCUMENT OWNER
A9: DI-IA-01 | B9: Audit Work Program (AWP) & Data Extraction Log | C9: Both (Physical/ Electronic) | D9: Internal Audit | E9: Audit Fieldwork, Sampling, and Evidence Gathering | F9: To determine procedures to perform and explicitly log what PI/SPI was extracted during the audit. | G9: Absence of data privacy consent (Legitimate Interest / Statutory mandate) | H9: Information obtained to prepare audit report | I9: Not shared (Internal Audit only) | J9: Secure locked cabinet / Encrypted Drive | K9: E.g., 3 years after the final audit report is approved | L9: No established retention period | M9: Cross-cut shredding / Secure digital wipe | N9: Internal Audit
A10: DI-IA-02 | B10: Internal Audit DPA Addendum & Independence Declaration | C10: Physical Form | D10: Internal Audit | E10: Auditor Independence & QA Management | F10: To ensure auditor objectivity and enforce DPA confidentiality and data handling rules. | G10: Consent obtained (Signed declaration) | I10: Not shared (HR & IA only) | J10: 201 Employee File / Compliance Folder | K10: E.g., 5 years post-employment | M10: Cross-cut shredding
A11: DI-IA-03 | B11: Incident / Whistleblower Report | C11: Both | D11: Internal Audit | E11: Fraud Investigation and Whistleblower Handling | F11: To document allegations of fraud or misconduct for independent investigation. | G11: Consent obtained / Legitimate Interest | I11: Legal Dept, Board of Directors (BOD) | J11: Restricted IA Database / Vault | K11: E.g., 10 years or until legal case resolution | M11: Secure digital wipe / Cross-cut shredding
A12: DI-IA-04 | B12: Final Audit Report | C12: Both | D12: Internal Audit | E12: Audit Reporting and Issue Tracking | F12: To report sanitized findings and assign operational accountability to management/BOD. | G12: Absence of data privacy consent | I12: BOD, Audit Committee, Dept Heads | J12: Data Center / Central Vault | K12: E.g., 5-10 years (Standard Corporate Record) | M12: Secure digital wipe / Shredding
A13: DI-IA-05 | B13: Audit Data Disposal Certificate/Log | C13: Electronic | D13: Internal Audit | E13: Audit Fieldwork, Sampling, and Evidence Gathering | F13: To serve as verifiable proof that raw data/evidence was securely destroyed after an audit. | G13: N/A | I13: DPO (For compliance verification) | J13: Encrypted IA Drive | K13: Permanent (Compliance Record) | M13: N/A

Sheet Data Fields_PIA
B2: FIRST COMMUNITY COOPERTIVE DATA INVENTORY
A9: No. | B9: DATA FIELD | C9: DOCUMENT | D9: Doc Ref No. | E9: GENERIC DATA CLASSIFICATION | F9: DATA CLASSIFICATION | G9: DATA SUBJECT CATEGORY | H9: PURPOSE OF COLLECTION | I9: REMARKS | J9: DOCUMENT OWNER
A10: 1 | B10: Specific Data Extracted (e.g., Names, Loan Balances) | C10: AWP & Data Extraction Log | D10: DI-IA-01 | F10: Sensitive Personal Information | G10: Member / Employee | H10: To track exactly what sensitive data the auditor pulled for control testing. | J10: Internal Audit
A11: 2 | B11: Justification for Extraction | C11: AWP & Data Extraction Log | D11: DI-IA-01 | F11: Non-personal Information | G11: N/A | H11: To enforce the Principle of Proportionality (Data Minimization). | J11: Internal Audit
A12: =A11+1 -> 3 | B12: Name of Auditor | C12: IA DPA Addendum & Independence Declaration | D12: DI-IA-02 | F12: Personal Information | G12: Employee (Auditor) | H12: To identify the auditor bound by the NDA. | J12: Internal Audit / HR
A13: =A12+1 -> 4 | B13: Declared Conflicts of Interest (e.g., family ties, business interests) | C13: IA DPA Addendum & Independence Declaration | D13: DI-IA-02 | F13: Sensitive Personal Information | G13: Employee (Auditor) | H13: To fulfill regulatory requirements for audit objectivity and independence. | J13: Internal Audit
A14: =A13+1 -> 5 | B14: Name of Complainant / Whistleblower | C14: Incident / Whistleblower Report | D14: DI-IA-03 | F14: Personal Information | G14: Employee / Member | H14: To establish the source of the allegation (often kept strictly confidential). | J14: Internal Audit
A15: =A14+1 -> 6 | B15: Allegation Details (Potential Offenses) | C15: Incident / Whistleblower Report | D15: DI-IA-03 | F15: Sensitive Personal Information (Offense/Legal) | G15: Employee / Member | H15: To provide grounds for the fraud/misconduct investigation. | J15: Internal Audit
A16: =A15+1 -> 7 | B16: Accountable Officer Name | C16: Final Audit Report | D16: DI-IA-04 | F16: Personal Information | G16: Employee | H16: To assign operational accountability for audit findings. | J16: Internal Audit
A17: =A16+1 -> 8 | B17: Administrative Sanction/Penalty Recommended | C17: Final Audit Report | D17: DI-IA-04 | F17: Sensitive Personal Information | G17: Employee | H17: To recommend remediation and disciplinary action to the Board/HR. | J17: Internal Audit

Sheet Documents
G9: DATA LIFE CYCLE
A10: Doc Ref No. | B10: DOCUMENT/ FILE NAME | C10: DOCUMENT TYPE | D10: DOCUMENT OWNER | E10: BUSINESS PROCESS | F10: DOCUMENT PURPOSE | G10: CONSENT IN COLLECTION | H10: USE | I10: SHARING | J10: STORAGE/REPOSITORY | K10: RETENTION PERIOD | L10: BASIS OF RETENTION | M10: DISPOSAL
A11: DI-BO-01 | B11: Membership Information Sheet | C11: Physical Form | D11: Branch Operations | E11: New accounts Management | F11: To obtain membership data for various applications | G11: Absence of data privacy consent | H11: Information obtained used for background check of applicant and approval of membership | I11: Shared to legal only if necessary | J11: File cabinet, electronic copies are stored in local computer | K11: No established retention period | L11: No established retention period | M11: No disposal policy and procedure. Per practice, idle forms are either shredded or sold when office clutter becomes an impediment in operation, or is no longer needed.
A12: DI-BO-02 | B12: Client Master: Maintenance | C12: Electronic | D12: Branch Operations | E12: New accounts Management | F12: To profile and identify current and former members | G12: Absence of data privacy consent | H12: Information obtained used for identification and profiling of members | I12: Shared to EdCom for reporting | J12: Data Center | K12: No established retention period | L12: No established retention period | M12: No disposal policy and procedure.Data retained since 1991.
A13: DI-BO-03 | B13: Personal Record Card | C13: Physical Form | D13: Branch Operations | E13: New accounts Management | F13: To obtain personal data for application of membership | G13: Absence of data privacy consent | H13: Information obtained used for background check of applicant and approval of membership | I13: Shared to other departments | J13: File cabinet, electronic copies are stored in local computer | K13: No established retention period | L13: No established retention period | M13: No disposal policy and procedure. Per practice, idle forms are either shredded or sold when office clutter becomes an impediment in operation, or is no longer needed.
A14: DI-BO-04 | B14: Loan Application | C14: Physical Form | D14: Branch Operations | E14: Loans Processing | F14: To obtain membership and loan data for application of loan | G14: Absence of data privacy consent | H14: Information obtained used for background check of applicant and approval of loan | I14: Shared to legal only if necessary | J14: File cabinet, electronic copies are stored in local computer | K14: No established retention period | L14: No established retention period | M14: No disposal policy and procedure. Per practice, idle forms are either shredded or sold when office clutter becomes an impediment in operation, or is no longer needed.
A15: DI-BO-05 | B15: Promissory Note | C15: Physical Form | D15: Branch Operations | E15: Loans Processing | F15: To complete required data fields in completion of promissiory note | G15: Absence of data privacy consent | H15: Information obtained used for background check of applicant and approval of loan | I15: Shared to legal only if necessary | J15: File cabinet, electronic copies are stored in local computer | K15: No established retention period | L15: No established retention period | M15: No disposal policy and procedure. Per practice, idle forms are either shredded or sold when office clutter becomes an impediment in operation, or is no longer needed.
A16: DI-BO-06 | B16: Co-maker's Statement | C16: Physical Form | D16: Branch Operations | E16: Loans Processing | F16: To complete required data fields in completion of co-maker's statement | G16: Absence of data privacy consent | H16: Information obtained used for background check of applicant and approval of loan | I16: Shared to legal only if necessary | J16: File cabinet, electronic copies are stored in local computer | K16: No established retention period | L16: No established retention period | M16: No disposal policy and procedure. Per practice, idle forms are either shredded or sold when office clutter becomes an impediment in operation, or is no longer needed.
A17: DI-BO-07 | B17: Pre-hospitalization/Medical Loan Application | C17: Physical Form | D17: Branch Operations | E17: Loans Processing | F17: To obtain personal data and details for application of pre-hospitalization/medical loan | G17: Absence of data privacy consent | H17: Information obtained used for background check of applicant and approval of loan | I17: Shared to legal only if necessary | J17: File cabinet, electronic copies are stored in local computer | K17: No established retention period | L17: No established retention period | M17: No disposal policy and procedure. Per practice, idle forms are either shredded or sold when office clutter becomes an impediment in operation, or is no longer needed.
A18: DI-BO-08 | B18: Commodity Loan Application | C18: Physical Form | D18: Branch Operations | E18: Loans Processing | F18: To obtain membership data and details for application of commodity loan | G18: Absence of data privacy consent | H18: Information obtained used for background check of applicant and approval of loan | I18: Shared to legal only if necessary | J18: File cabinet, electronic copies are stored in local computer | K18: No established retention period | L18: No established retention period | M18: No disposal policy and procedure. Per practice, idle forms are either shredded or sold when office clutter becomes an impediment in operation, or is no longer needed.
A19: DI-BO-09 | B19: Petty Cash Loan Application | C19: Physical Form | D19: Branch Operations | E19: Loans Processing | F19: To obtain membership data for application of petty cash loan | G19: Absence of data privacy consent | H19: Information obtained used for background check of applicant and approval of loan | I19: Shared to legal only if necessary | J19: File cabinet, electronic copies are stored in local computer | K19: No established retention period | L19: No established retention period | M19: No disposal policy and procedure. Per practice, idle forms are either shredded or sold when office clutter becomes an impediment in operation, or is no longer needed.
A20: DI-BO-10 | B20: SM/Ororama/GC Gift Cheque Loan Application | C20: Physical Form | D20: Branch Operations | E20: Loans Processing | F20: To obtain membership data for application of GC Loan | G20: Absence of data privacy consent | H20: Information obtained used for background check of applicant and approval of loan | I20: Shared to legal only if necessary | J20: File cabinet, electronic copies are stored in local computer | K20: No established retention period | L20: No established retention period | M20: No disposal policy and procedure. Per practice, idle forms are either shredded or sold when office clutter becomes an impediment in operation, or is no longer needed.
A21: DI-BO-11 | B21: Rice Loan Application & Promissory Note | C21: Physical Form | D21: Branch Operations | E21: Loans Processing | F21: To obtain membership data for application of Rice Loan | G21: Absence of data privacy consent | H21: Information obtained used for background check of applicant and approval of loan | I21: Shared to legal only if necessary | J21: File cabinet, electronic copies are stored in local computer | K21: No established retention period | L21: No established retention period | M21: No disposal policy and procedure. Per practice, idle forms are either shredded or sold when office clutter becomes an impediment in operation, or is no longer needed.
... A101: DI-AM-01 | B101: Pre-Qualification Checklist | C101: Physical Form | D101: Asset Management | E101: Construction Management | F101: To determine bidders' qualifications | G101: Absence of data privacy consent | H101: Information obtained to ensure bidders are qualified for construction projects | I101: Not shared | J101: File cabinet | K101: No established retention period | L101: No established retention period | M101: No disposal policy and procedure. Per practice, idle forms are either shredded or sold when office clutter becomes an impediment in operation, or is no longer needed.

Sheet Data Fields
B9: No. | C9: DATA FIELD | D9: DOCUMENT | E9: Doc Ref No. | F9: GENERIC DATA CLASSIFICATION | G9: DATA CLASSIFICATION | H9: DATA SUBJECT CATEGORY | I9: PURPOSE OF COLLECTION | J9: REMARKS | K9: DOCUMENT OWNER
B10: 1 | C10: Name | D10: Membership Information Sheet | E10: DI-BO-01 | G10: Personal Information | H10: Member | I10: To determine the name of the borrower | K10: Branch Operations
B11: 2 | C11: Age | D11: Membership Information Sheet | E11: DI-BO-01 | G11: Sensitive Personal Information | H11: Member | I11: To determine the age of the borrower | K11: Branch Operations
B12: 3 | C12: Gender | D12: Membership Information Sheet | E12: DI-BO-01 | G12: Sensitive Personal Information | H12: Member | I12: To determine the gender of the borrower | K12: Branch Operations
B13: 4 | C13: Place of birth | D13: Membership Information Sheet | E13: DI-BO-01 | G13: Personal Information | H13: Member | I13: To determine the place of birth of the borrower | K13: Branch Operations
B14: 5 | C14: Date of birth | D14: Membership Information Sheet | E14: DI-BO-01 | G14: Personal Information | H14: Member | I14: To determine the date of birth of the borrower | K14: Branch Operations
B15: 6 | C15: Nationality | D15: Membership Information Sheet | E15: DI-BO-01 | G15: Sensitive Personal Information | H15: Member | I15: To determine the nationality of the borrower | K15: Branch Operations
B16: 7 | C16: Civil Status | D16: Membership Information Sheet | E16: DI-BO-01 | G16: Sensitive Personal Information | H16: Member | I16: To determine the civil status of the borrower | K16: Branch Operations
B17: 8 | C17: Blood Type | D17: Membership Information Sheet | E17: DI-BO-01 | G17: Sensitive Personal Information | H17: Member | I17: To determine the blood type of the borrower | K17: Branch Operations
B18: 9 | C18: Present Address | D18: Membership Information Sheet | E18: DI-BO-01 | G18: Personal Information | H18: Member | I18: To determine the present address of the borrower | K18: Branch Operations
B19: 10 | C19: # of years in this address | D19: Membership Information Sheet | E19: DI-BO-01 | G19: Sensitive Personal Information | H19: Member | I19: To determine the length of stay of the borrower in the present address | K19: Branch Operations
B20: 11 | C20: Previous Address | D20: Membership Information Sheet | E20: DI-BO-01 | G20: Personal Information | H20: Member | I20: To determine the previous address of the borrower | K20: Branch Operations
B21: 12 | C21: # of years in this address | D21: Membership Information Sheet | E21: DI-BO-01 | G21: Sensitive Personal Information | H21: Member | I21: To determine the length of stay of the borrower in the previous address | K21: Branch Operations
... B2390: 2381 | C2390: Total | D2390: Final Demand Letter | E2390: DI-LD-01 | G2390: Non-personal Information | H2390: Member | I2390: To demand collection from delinquent account | K2390: Legal Department
B2391: 2382 | C2391: Civil Case No. | D2391: Statement of Claim | E2391: DI-LD-02 | G2391: Sensitive Personal Information | H2391: Member | I2391: To fill out information for filing of case to RTC | J2391: RTC Form | K2391: Legal Department
B2392: 2383 | C2392: Name of Plantiff/s | D2392: Statement of Claim | E2392: DI-LD-02 | G2392: Personal Information | H2392: Member | I2392: To fill out information for filing of case to RTC | J2392: RTC Form | K2392: Legal Department
B2393: 2384 | C2393: Sex | D2393: Statement of Claim | E2393: DI-LD-02 | G2393: Personal Information | H2393: Member | I2393: To fill out information for filing of case to RTC | J2393: RTC Form | K2393: Legal Department
B2394: 2385 | C2394: Age | D2394: Statement of Claim | E2394: DI-LD-02 | G2394: Personal Information | H2394: Member | I2394: To fill out information for filing of case to RTC | J2394: RTC Form | K2394: Legal Department
B2395: 2386 | C2395: Civil Status | D2395: Statement of Claim | E2395: DI-LD-02 | G2395: Sensitive Personal Information | H2395: Member | I2395: To fill out information for filing of case to RTC | J2395: RTC Form | K2395: Legal Department
B2396: 2387 | C2396: Individual | D2396: Statement of Claim | E2396: DI-LD-02 | G2396: Personal Information | H2396: Member | I2396: To fill out information for filing of case to RTC | J2396: RTC Form | K2396: Legal Department
B2397: 2388 | C2397: Corporation | D2397: Statement of Claim | E2397: DI-LD-02 | G2397: Non-personal Information | H2397: Member | I2397: To fill out information for filing of case to RTC | J2397: RTC Form | K2397: Legal Department
B2398: 2389 | C2398: Partnership | D2398: Statement of Claim | E2398: DI-LD-02 | G2398: Non-personal Information | H2398: Member | I2398: To fill out information for filing of case to RTC | J2398: RTC Form | K2398: Legal Department
B2399: 2390 | C2399: Cooperative | D2399: Statement of Claim | E2399: DI-LD-02 | G2399: Non-personal Information | H2399: Member | I2399: To fill out information for filing of case to RTC | J2399: RTC Form | K2399: Legal Department
B2400: 2391 | C2400: Sole Proprietorship | D2400: Statement of Claim | E2400: DI-LD-02 | G2400: Non-personal Information | H2400: Member | I2400: To fill out information for filing of case to RTC | J2400: RTC Form | K2400: Legal Department
B2401: 2392 | C2401: Nature of Business | D2401: Statement of Claim | E2401: DI-LD-02 | G2401: Personal Information | H2401: Member | I2401: To fill out information for filing of case to RTC | J2401: RTC Form | K2401: Legal Department
B2402: 2393 | C2402: Plaintiff's Home Address City | D2402: Statement of Claim | E2402: DI-LD-02 | G2402: Personal Information | H2402: Member | I2402: To fill out information for filing of case to RTC | J2402: RTC Form | K2402: Legal Department
... B2463: 2454 | C2463: How many small claims cases have you filed within this calendar year prior to this present case, in this court station and in the entire country: | D2463: Statement of Claim | E2463: DI-LD-02 | G2463: Non-personal Information | H2463: Member | I2463: To fill out information for filing of case to RTC | J2463: RTC Form | K2463: Legal Department
B2464: 2455 | C2464: Borrowers: | D2464: Statement of Account | E2464: DI-LD-03 | G2464: Personal Information | H2464: Member | I2464: Required details for filing of case to RTC | K2464: Legal Department
B2465: 2456 | C2465: Type of Loan: | D2465: Statement of Account | E2465: DI-LD-03 | G2465: Sensitive Personal Information | H2465: Member | I2465: Required details for filing of case to RTC | K2465: Legal Department
B2466: 2457 | C2466: Principal Balance: | D2466: Statement of Account | E2466: DI-LD-03 | G2466: Non-personal Information | H2466: Member | I2466: Required details for filing of case to RTC | K2466: Legal Department
B2467: 2458 | C2467: Interest: | D2467: Statement of Account | E2467: DI-LD-03 | G2467: Non-personal Information | H2467: Member | I2467: Required details for filing of case to RTC | K2467: Legal Department
B2468: 2459 | C2468: Fines: | D2468: Statement of Account | E2468: DI-LD-03 | G2468: Non-personal Information | H2468: Member | I2468: Required details for filing of case to RTC | K2468: Legal Department
B2469: 2460 | C2469: Attorney's Fee | D2469: Statement of Account | E2469: DI-LD-03 | G2469: Non-personal Information | H2469: Member | I2469: Required details for filing of case to RTC | K2469: Legal Department
B2470: 2461 | C2470: Expenses | D2470: Statement of Account | E2470: DI-LD-03 | G2470: Non-personal Information | H2470: Member | I2470: Required details for filing of case to RTC | K2470: Legal Department
B2471: 2462 | C2471: Total Amount | D2471: Statement of Account | E2471: DI-LD-03 | G2471: Non-personal Information | H2471: Member | I2471: Required details for filing of case to RTC | K2471: Legal Department
B2472: 2463 | C2472: Computed by: Accountant | D2472: Statement of Account | E2472: DI-LD-03 | G2472: Sensitive Personal Information | H2472: Member | I2472: Required details for filing of case to RTC | K2472: Legal Department
B2473: 2464 | C2473: Date | D2473: Visitors' Logbook | E2473: DI-AD-01 | G2473: Personal Information | H2473: Visitors | I2473: To determine the date | K2473: Administrative department
B2474: 2465 | C2474: Time in | D2474: Visitors' Logbook | E2474: DI-AD-01 | G2474: Personal Information | H2474: Visitors | I2474: To determine the time in of the visitor | K2474: Administrative department
B2475: 2466 | C2475: Name | D2475: Visitors' Logbook | E2475: DI-AD-01 | G2475: Personal Information | H2475: Visitors | I2475: To determine the name of the visitor | K2475: Administrative department
... B2597: 2588 | C2597: Teller | D2597: Savings Deposit Passbook | E2597: DI-BO-28 | G2597: Sensitive Personal Information | H2597: Member | I2597: To determine the Teller of the transaction of member | K2597: Branch Operations
...

Sheet Branch Operations
B9: No. | C9: DATA FIELD | D9: DOCUMENT | E9: Doc Ref No. | F9: GENERIC DATA CLASSIFICATION | G9: DATA CLASSIFICATION | H9: DATA SUBJECT CATEGORY | I9: PURPOSE OF COLLECTION | J9: REMARKS | K9: DOCUMENT OWNER
B10: 1 | C10: =IFERROR(INDEX('Data Fields'!$B:$K,MATCH($B10,'Data Fields'!$B:$B,0),MATCH(B$9,'Data Fields'!$9:$9,0)),0) -> Name | D10: =IFERROR(INDEX('Data Fields'!$B:$K,MATCH($B10,'Data Fields'!$B:$B,0),MATCH(C$9,'Data Fields'!$9:$9,0)),0) -> Membership Information Sheet | E10: =IFERROR(INDEX('Data Fields'!$B:$K,MATCH($B10,'Data Fields'!$B:$B,0),MATCH(D$9,'Data Fields'!$9:$9,0)),0) -> DI-BO-01 | F10: =IFERROR(INDEX('Data Fields'!$B:$K,MATCH($B10,'Data Fields'!$B:$B,0),MATCH(E$9,'Data Fields'!$9:$9,0)),0) -> 0 | G10: =IFERROR(INDEX('Data Fields'!$B:$K,MATCH($B10,'Data Fields'!$B:$B,0),MATCH(F$9,'Data Fields'!$9:$9,0)),0) -> Personal Information | H10: =IFERROR(INDEX('Data Fields'!$B:$K,MATCH($B10,'Data Fields'!$B:$B,0),MATCH(G$9,'Data Fields'!$9:$9,0)),0) -> Member | I10: =IFERROR(INDEX('Data Fields'!$B:$K,MATCH($B10,'Data Fields'!$B:$B,0),MATCH(H$9,'Data Fields'!$9:$9,0)),0) -> To determine the name of the borrower | J10: =IFERROR(INDEX('Data Fields'!$B:$K,MATCH($B10,'Data Fields'!$B:$B,0),MATCH(I$9,'Data Fields'!$9:$9,0)),0) -> 0 | K10: =IFERROR(INDEX('Data Fields'!$B:$K,MATCH($B10,'Data Fields'!$B:$B,0),MATCH(J$9,'Data Fields'!$9:$9,0)),0) -> Branch Operations
B11: 2 | C11: =IFERROR(INDEX('Data Fields'!$B:$K,MATCH($B11,'Data Fields'!$B:$B,0),MATCH(B$9,'Data Fields'!$9:$9,0)),0) -> Age | D11: =IFERROR(INDEX('Data Fields'!$B:$K,MATCH($B11,'Data Fields'!$B:$B,0),MATCH(C$9,'Data Fields'!$9:$9,0)),0) -> Membership Information Sheet | E11: =IFERROR(INDEX('Data Fields'!$B:$K,MATCH($B11,'Data Fields'!$B:$B,0),MATCH(D$9,'Data Fields'!$9:$9,0)),0) -> DI-BO-01 | F11: =IFERROR(INDEX('Data Fields'!$B:$K,MATCH($B11,'Data Fields'!$B:$B,0),MATCH(E$9,'Data Fields'!$9:$9,0)),0) -> 0 | G11: =IFERROR(INDEX('Data Fields'!$B:$K,MATCH($B11,'Data Fields'!$B:$B,0),MATCH(F$9,'Data Fields'!$9:$9,0)),0) -> Sensitive Personal Information | H11: =IFERROR(INDEX('Data Fields'!$B:$K,MATCH($B11,'Data Fields'!$B:$B,0),MATCH(G$9,'Data Fields'!$9:$9,0)),0) -> Member | I11: =IFERROR(INDEX('Data Fields'!$B:$K,MATCH($B11,'Data Fields'!$B:$B,0),MATCH(H$9,'Data Fields'!$9:$9,0)),0) -> To determine the age of the borrower | J11: =IFERROR(INDEX('Data Fields'!$B:$K,MATCH($B11,'Data Fields'!$B:$B,0),MATCH(I$9,'Data Fields'!$9:$9,0)),0) -> 0 | K11: =IFERROR(INDEX('Data Fields'!$B:$K,MATCH($B11,'Data Fields'!$B:$B,0),MATCH(J$9,'Data Fields'!$9:$9,0)),0) -> Branch Operations
B12: 3 | C12: =IFERROR(INDEX('Data Fields'!$B:$K,MATCH($B12,'Data Fields'!$B:$B,0),MATCH(B$9,'Data Fields'!$9:$9,0)),0) -> Gender | D12: =IFERROR(INDEX('Data Fields'!$B:$K,MATCH($B12,'Data Fields'!$B:$B,0),MATCH(C$9,'Data Fields'!$9:$9,0)),0) -> Membership Information Sheet | E12: =IFERROR(INDEX('Data Fields'!$B:$K,MATCH($B12,'Data Fields'!$B:$B,0),MATCH(D$9,'Data Fields'!$9:$9,0)),0) -> DI-BO-01 | F12: =IFERROR(INDEX('Data Fields'!$B:$K,MATCH($B12,'Data Fields'!$B:$B,0),MATCH(E$9,'Data Fields'!$9:$9,0)),0) -> 0 | G12: =IFERROR(INDEX('Data Fields'!$B:$K,MATCH($B12,'Data Fields'!$B:$B,0),MATCH(F$9,'Data Fields'!$9:$9,0)),0) -> Sensitive Personal Information | H12: =IFERROR(INDEX('Data Fields'!$B:$K,MATCH($B12,'Data Fields'!$B:$B,0),MATCH(G$9,'Data Fields'!$9:$9,0)),0) -> Member | I12: =IFERROR(INDEX('Data Fields'!$B:$K,MATCH($B12,'Data Fields'!$B:$B,0),MATCH(H$9,'Data Fields'!$9:$9,0)),0) -> To determine the gender of the borrower | J12: =IFERROR(INDEX('Data Fields'!$B:$K,MATCH($B12,'Data Fields'!$B:$B,0),MATCH(I$9,'Data Fields'!$9:$9,0)),0) -> 0 | K12: =IFERROR(INDEX('Data Fields'!$B:$K,MATCH($B12,'Data Fields'!$B:$B,0),MATCH(J$9,'Data Fields'!$9:$9,0)),0) -> Branch Operations
B13: 4 | C13: =IFERROR(INDEX('Data Fields'!$B:$K,MATCH($B13,'Data Fields'!$B:$B,0),MATCH(B$9,'Data Fields'!$9:$9,0)),0) -> Place of birth | D13: =IFERROR(INDEX('Data Fields'!$B:$K,MATCH($B13,'Data Fields'!$B:$B,0),MATCH(C$9,'Data Fields'!$9:$9,0)),0) -> Membership Information Sheet | E13: =IFERROR(INDEX('Data Fields'!$B:$K,MATCH($B13,'Data Fields'!$B:$B,0),MATCH(D$9,'Data Fields'!$9:$9,0)),0) -> DI-BO-01 | F13: =IFERROR(INDEX('Data Fields'!$B:$K,MATCH($B13,'Data Fields'!$B:$B,0),MATCH(E$9,'Data Fields'!$9:$9,0)),0) -> 0 | G13: =IFERROR(INDEX('Data Fields'!$B:$K,MATCH($B13,'Data Fields'!$B:$B,0),MATCH(F$9,'Data Fields'!$9:$9,0)),0) -> Personal Information | H13: =IFERROR(INDEX('Data Fields'!$B:$K,MATCH($B13,'Data Fields'!$B:$B,0),MATCH(G$9,'Data Fields'!$9:$9,0)),0) -> Member | I13: =IFERROR(INDEX('Data Fields'!$B:$K,MATCH($B13,'Data Fields'!$B:$B,0),MATCH(H$9,'Data Fields'!$9:$9,0)),0) -> To determine the place of birth of the borrower | J13: =IFERROR(INDEX('Data Fields'!$B:$K,MATCH($B13,'Data Fields'!$B:$B,0),MATCH(I$9,'Data Fields'!$9:$9,0)),0) -> 0 | K13: =IFERROR(INDEX('Data Fields'!$B:$K,MATCH($B13,'Data Fields'!$B:$B,0),MATCH(J$9,'Data Fields'!$9:$9,0)),0) -> Branch Operations
B14: 5 | C14: =IFERROR(INDEX('Data Fields'!$B:$K,MATCH($B14,'Data Fields'!$B:$B,0),MATCH(B$9,'Data Fields'!$9:$9,0)),0) -> Date of birth | D14: =IFERROR(INDEX('Data Fields'!$B:$K,MATCH($B14,'Data Fields'!$B:$B,0),MATCH(C$9,'Data Fields'!$9:$9,0)),0) -> Membership Information Sheet | E14: =IFERROR(INDEX('Data Fields'!$B:$K,MATCH($B14,'Data Fields'!$B:$B,0),MATCH(D$9,'Data Fields'!$9:$9,0)),0) -> DI-BO-01 | F14: =IFERROR(INDEX('Data Fields'!$B:$K,MATCH($B14,'Data Fields'!$B:$B,0),MATCH(E$9,'Data Fields'!$9:$9,0)),0) -> 0 | G14: =IFERROR(INDEX('Data Fields'!$B:$K,MATCH($B14,'Data Fields'!$B:$B,0),MATCH(F$9,'Data Fields'!$9:$9,0)),0) -> Personal Information | H14: =IFERROR(INDEX('Data Fields'!$B:$K,MATCH($B14,'Data Fields'!$B:$B,0),MATCH(G$9,'Data Fields'!$9:$9,0)),0) -> Member | I14: =IFERROR(INDEX('Data Fields'!$B:$K,MATCH($B14,'Data Fields'!$B:$B,0),MATCH(H$9,'Data Fields'!$9:$9,0)),0) -> To determine the date of birth of the borrower | J14: =IFERROR(INDEX('Data Fields'!$B:$K,MATCH($B14,'Data Fields'!$B:$B,0),MATCH(I$9,'Data Fields'!$9:$9,0)),0) -> 0 | K14: =IFERROR(INDEX('Data Fields'!$B:$K,MATCH($B14,'Data Fields'!$B:$B,0),MATCH(J$9,'Data Fields'!$9:$9,0)),0) -> Branch Operations
B15: 6 | C15: =IFERROR(INDEX('Data Fields'!$B:$K,MATCH($B15,'Data Fields'!$B:$B,0),MATCH(B$9,'Data Fields'!$9:$9,0)),0) -> Nationality | D15: =IFERROR(INDEX('Data Fields'!$B:$K,MATCH($B15,'Data Fields'!$B:$B,0),MATCH(C$9,'Data Fields'!$9:$9,0)),0) -> Membership Information Sheet | E15: =IFERROR(INDEX('Data Fields'!$B:$K,MATCH($B15,'Data Fields'!$B:$B,0),MATCH(D$9,'Data Fields'!$9:$9,0)),0) -> DI-BO-01 | F15: =IFERROR(INDEX('Data Fields'!$B:$K,MATCH($B15,'Data Fields'!$B:$B,0),MATCH(E$9,'Data Fields'!$9:$9,0)),0) -> 0 | G15: =IFERROR(INDEX('Data Fields'!$B:$K,MATCH($B15,'Data Fields'!$B:$B,0),MATCH(F$9,'Data Fields'!$9:$9,0)),0) -> Sensitive Personal Information | H15: =IFERROR(INDEX('Data Fields'!$B:$K,MATCH($B15,'Data Fields'!$B:$B,0),MATCH(G$9,'Data Fields'!$9:$9,0)),0) -> Member | I15: =IFERROR(INDEX('Data Fields'!$B:$K,MATCH($B15,'Data Fields'!$B:$B,0),MATCH(H$9,'Data Fields'!$9:$9,0)),0) -> To determine the nationality of the borrower | J15: =IFERROR(INDEX('Data Fields'!$B:$K,MATCH($B15,'Data Fields'!$B:$B,0),MATCH(I$9,'Data Fields'!$9:$9,0)),0) -> 0 | K15: =IFERROR(INDEX('Data Fields'!$B:$K,MATCH($B15,'Data Fields'!$B:$B,0),MATCH(J$9,'Data Fields'!$9:$9,0)),0) -> Branch Operations
B16: 7 | C16: =IFERROR(INDEX('Data Fields'!$B:$K,MATCH($B16,'Data Fields'!$B:$B,0),MATCH(B$9,'Data Fields'!$9:$9,0)),0) -> Civil Status | D16: =IFERROR(INDEX('Data Fields'!$B:$K,MATCH($B16,'Data Fields'!$B:$B,0),MATCH(C$9,'Data Fields'!$9:$9,0)),0) -> Membership Information Sheet | E16: =IFERROR(INDEX('Data Fields'!$B:$K,MATCH($B16,'Data Fields'!$B:$B,0),MATCH(D$9,'Data Fields'!$9:$9,0)),0) -> DI-BO-01 | F16: =IFERROR(INDEX('Data Fields'!$B:$K,MATCH($B16,'Data Fields'!$B:$B,0),MATCH(E$9,'Data Fields'!$9:$9,0)),0) -> 0 | G16: =IFERROR(INDEX('Data Fields'!$B:$K,MATCH($B16,'Data Fields'!$B:$B,0),MATCH(F$9,'Data Fields'!$9:$9,0)),0) -> Sensitive Personal Information | H16: =IFERROR(INDEX('Data Fields'!$B:$K,MATCH($B16,'Data Fields'!$B:$B,0),MATCH(G$9,'Data Fields'!$9:$9,0)),0) -> Member | I16: =IFERROR(INDEX('Data Fields'!$B:$K,MATCH($B16,'Data Fields'!$B:$B,0),MATCH(H$9,'Data Fields'!$9:$9,0)),0) -> To determine the civil status of the borrower | J16: =IFERROR(INDEX('Data Fields'!$B:$K,MATCH($B16,'Data Fields'!$B:$B,0),MATCH(I$9,'Data Fields'!$9:$9,0)),0) -> 0 | K16: =IFERROR(INDEX('Data Fields'!$B:$K,MATCH($B16,'Data Fields'!$B:$B,0),MATCH(J$9,'Data Fields'!$9:$9,0)),0) -> Branch Operations
B17: 8 | C17: =IFERROR(INDEX('Data Fields'!$B:$K,MATCH($B17,'Data Fields'!$B:$B,0),MATCH(B$9,'Data Fields'!$9:$9,0)),0) -> Blood Type | D17: =IFERROR(INDEX('Data Fields'!$B:$K,MATCH($B17,'Data Fields'!$B:$B,0),MATCH(C$9,'Data Fields'!$9:$9,0)),0) -> Membership Information Sheet | E17: =IFERROR(INDEX('Data Fields'!$B:$K,MATCH($B17,'Data Fields'!$B:$B,0),MATCH(D$9,'Data Fields'!$9:$9,0)),0) -> DI-BO-01 | F17: =IFERROR(INDEX('Data Fields'!$B:$K,MATCH($B17,'Data Fields'!$B:$B,0),MATCH(E$9,'Data Fields'!$9:$9,0)),0) -> 0 | G17: =IFERROR(INDEX('Data Fields'!$B:$K,MATCH($B17,'Data Fields'!$B:$B,0),MATCH(F$9,'Data Fields'!$9:$9,0)),0) -> Sensitive Personal Information | H17: =IFERROR(INDEX('Data Fields'!$B:$K,MATCH($B17,'Data Fields'!$B:$B,0),MATCH(G$9,'Data Fields'!$9:$9,0)),0) -> Member | I17: =IFERROR(INDEX('Data Fields'!$B:$K,MATCH($B17,'Data Fields'!$B:$B,0),MATCH(H$9,'Data Fields'!$9:$9,0)),0) -> To determine the blood type of the borrower | J17: =IFERROR(INDEX('Data Fields'!$B:$K,MATCH($B17,'Data Fields'!$B:$B,0),MATCH(I$9,'Data Fields'!$9:$9,0)),0) -> 0 | K17: =IFERROR(INDEX('Data Fields'!$B:$K,MATCH($B17,'Data Fields'!$B:$B,0),MATCH(J$9,'Data Fields'!$9:$9,0)),0) -> Branch Operations
B18: 9 | C18: =IFERROR(INDEX('Data Fields'!$B:$K,MATCH($B18,'Data Fields'!$B:$B,0),MATCH(B$9,'Data Fields'!$9:$9,0)),0) -> Present Address | D18: =IFERROR(INDEX('Data Fields'!$B:$K,MATCH($B18,'Data Fields'!$B:$B,0),MATCH(C$9,'Data Fields'!$9:$9,0)),0) -> Membership Information Sheet | E18: =IFERROR(INDEX('Data Fields'!$B:$K,MATCH($B18,'Data Fields'!$B:$B,0),MATCH(D$9,'Data Fields'!$9:$9,0)),0) -> DI-BO-01 | F18: =IFERROR(INDEX('Data Fields'!$B:$K,MATCH($B18,'Data Fields'!$B:$B,0),MATCH(E$9,'Data Fields'!$9:$9,0)),0) -> 0 | G18: =IFERROR(INDEX('Data Fields'!$B:$K,MATCH($B18,'Data Fields'!$B:$B,0),MATCH(F$9,'Data Fields'!$9:$9,0)),0) -> Personal Information | H18: =IFERROR(INDEX('Data Fields'!$B:$K,MATCH($B18,'Data Fields'!$B:$B,0),MATCH(G$9,'Data Fields'!$9:$9,0)),0) -> Member | I18: =IFERROR(INDEX('Data Fields'!$B:$K,MATCH($B18,'Data Fields'!$B:$B,0),MATCH(H$9,'Data Fields'!$9:$9,0)),0) -> To determine the present address of the borrower | J18: =IFERROR(INDEX('Data Fields'!$B:$K,MATCH($B18,'Data Fields'!$B:$B,0),MATCH(I$9,'Data Fields'!$9:$9,0)),0) -> 0 | K18: =IFERROR(INDEX('Data Fields'!$B:$K,MATCH($B18,'Data Fields'!$B:$B,0),MATCH(J$9,'Data Fields'!$9:$9,0)),0) -> Branch Operations
B19: 10 | C19: =IFERROR(INDEX('Data Fields'!$B:$K,MATCH($B19,'Data Fields'!$B:$B,0),MATCH(B$9,'Data Fields'!$9:$9,0)),0) -> # of years in this address | D19: =IFERROR(INDEX('Data Fields'!$B:$K,MATCH($B19,'Data Fields'!$B:$B,0),MATCH(C$9,'Data Fields'!$9:$9,0)),0) -> Membership Information Sheet | E19: =IFERROR(INDEX('Data Fields'!$B:$K,MATCH($B19,'Data Fields'!$B:$B,0),MATCH(D$9,'Data Fields'!$9:$9,0)),0) -> DI-BO-01 | F19: =IFERROR(INDEX('Data Fields'!$B:$K,MATCH($B19,'Data Fields'!$B:$B,0),MATCH(E$9,'Data Fields'!$9:$9,0)),0) -> 0 | G19: =IFERROR(INDEX('Data Fields'!$B:$K,MATCH($B19,'Data Fields'!$B:$B,0),MATCH(F$9,'Data Fields'!$9:$9,0)),0) -> Sensitive Personal Information | H19: =IFERROR(INDEX('Data Fields'!$B:$K,MATCH($B19,'Data Fields'!$B:$B,0),MATCH(G$9,'Data Fields'!$9:$9,0)),0) -> Member | I19: =IFERROR(INDEX('Data Fields'!$B:$K,MATCH($B19,'Data Fields'!$B:$B,0),MATCH(H$9,'Data Fields'!$9:$9,0)),0) -> To determine the length of stay of the borrower in the present address | J19: =IFERROR(INDEX('Data Fields'!$B:$K,MATCH($B19,'Data Fields'!$B:$B,0),MATCH(I$9,'Data Fields'!$9:$9,0)),0) -> 0 | K19: =IFERROR(INDEX('Data Fields'!$B:$K,MATCH($B19,'Data Fields'!$B:$B,0),MATCH(J$9,'Data Fields'!$9:$9,0)),0) -> Branch Operations
B20: 11 | C20: =IFERROR(INDEX('Data Fields'!$B:$K,MATCH($B20,'Data Fields'!$B:$B,0),MATCH(B$9,'Data Fields'!$9:$9,0)),0) -> Previous Address | D20: =IFERROR(INDEX('Data Fields'!$B:$K,MATCH($B20,'Data Fields'!$B:$B,0),MATCH(C$9,'Data Fields'!$9:$9,0)),0) -> Membership Information Sheet | E20: =IFERROR(INDEX('Data Fields'!$B:$K,MATCH($B20,'Data Fields'!$B:$B,0),MATCH(D$9,'Data Fields'!$9:$9,0)),0) -> DI-BO-01 | F20: =IFERROR(INDEX('Data Fields'!$B:$K,MATCH($B20,'Data Fields'!$B:$B,0),MATCH(E$9,'Data Fields'!$9:$9,0)),0) -> 0 | G20: =IFERROR(INDEX('Data Fields'!$B:$K,MATCH($B20,'Data Fields'!$B:$B,0),MATCH(F$9,'Data Fields'!$9:$9,0)),0) -> Personal Information | H20: =IFERROR(INDEX('Data Fields'!$B:$K,MATCH($B20,'Data Fields'!$B:$B,0),MATCH(G$9,'Data Fields'!$9:$9,0)),0) -> Member | I20: =IFERROR(INDEX('Data Fields'!$B:$K,MATCH($B20,'Data Fields'!$B:$B,0),MATCH(H$9,'Data Fields'!$9:$9,0)),0) -> To determine the previous address of the borrower | J20: =IFERROR(INDEX('Data Fields'!$B:$K,MATCH($B20,'Data Fields'!$B:$B,0),MATCH(I$9,'Data Fields'!$9:$9,0)),0) -> 0 | K20: =IFERROR(INDEX('Data Fields'!$B:$K,MATCH($B20,'Data Fields'!$B:$B,0),MATCH(J$9,'Data Fields'!$9:$9,0)),0) -> Branch Operations
B21: 12 | C21: =IFERROR(INDEX('Data Fields'!$B:$K,MATCH($B21,'Data Fields'!$B:$B,0),MATCH(B$9,'Data Fields'!$9:$9,0)),0) -> # of years in this address | D21: =IFERROR(INDEX('Data Fields'!$B:$K,MATCH($B21,'Data Fields'!$B:$B,0),MATCH(C$9,'Data Fields'!$9:$9,0)),0) -> Membership Information Sheet | E21: =IFERROR(INDEX('Data Fields'!$B:$K,MATCH($B21,'Data Fields'!$B:$B,0),MATCH(D$9,'Data Fields'!$9:$9,0)),0) -> DI-BO-01 | F21: =IFERROR(INDEX('Data Fields'!$B:$K,MATCH($B21,'Data Fields'!$B:$B,0),MATCH(E$9,'Data Fields'!$9:$9,0)),0) -> 0 | G21: =IFERROR(INDEX('Data Fields'!$B:$K,MATCH($B21,'Data Fields'!$B:$B,0),MATCH(F$9,'Data Fields'!$9:$9,0)),0) -> Sensitive Personal Information | H21: =IFERROR(INDEX('Data Fields'!$B:$K,MATCH($B21,'Data Fields'!$B:$B,0),MATCH(G$9,'Data Fields'!$9:$9,0)),0) -> Member | I21: =IFERROR(INDEX('Data Fields'!$B:$K,MATCH($B21,'Data Fields'!$B:$B,0),MATCH(H$9,'Data Fields'!$9:$9,0)),0) -> To determine the length of stay of the borrower in the previous address | J21: =IFERROR(INDEX('Data Fields'!$B:$K,MATCH($B21,'Data Fields'!$B:$B,0),MATCH(I$9,'Data Fields'!$9:$9,0)),0) -> 0 | K21: =IFERROR(INDEX('Data Fields'!$B:$K,MATCH($B21,'Data Fields'!$B:$B,0),MATCH(J$9,'Data Fields'!$9:$9,0)),0) -> Branch Operations
... B926: 2517 | C926: =IFERROR(INDEX('Data Fields'!$B:$K,MATCH($B926,'Data Fields'!$B:$B,0),MATCH(B$9,'Data Fields'!$9:$9,0)),0) -> Interviewed by | D926: =IFERROR(INDEX('Data Fields'!$B:$K,MATCH($B926,'Data Fields'!$B:$B,0),MATCH(C$9,'Data Fields'!$9:$9,0)),0) -> Credit Committee slip | E926: =IFERROR(INDEX('Data Fields'!$B:$K,MATCH($B926,'Data Fields'!$B:$B,0),MATCH(D$9,'Data Fields'!$9:$9,0)),0) -> DI-BO-22 | F926: =IFERROR(INDEX('Data Fields'!$B:$K,MATCH($B926,'Data Fields'!$B:$B,0),MATCH(E$9,'Data Fields'!$9:$9,0)),0) -> 0 | G926: =IFERROR(INDEX('Data Fields'!$B:$K,MATCH($B926,'Data Fields'!$B:$B,0),MATCH(F$9,'Data Fields'!$9:$9,0)),0) -> Sensitive Personal Information | H926: =IFERROR(INDEX('Data Fields'!$B:$K,MATCH($B926,'Data Fields'!$B:$B,0),MATCH(G$9,'Data Fields'!$9:$9,0)),0) -> Member | I926: =IFERROR(INDEX('Data Fields'!$B:$K,MATCH($B926,'Data Fields'!$B:$B,0),MATCH(H$9,'Data Fields'!$9:$9,0)),0) -> To determine who interviewed the borrower | J926: =IFERROR(INDEX('Data Fields'!$B:$K,MATCH($B926,'Data Fields'!$B:$B,0),MATCH(I$9,'Data Fields'!$9:$9,0)),0) -> 0 | K926: =IFERROR(INDEX('Data Fields'!$B:$K,MATCH($B926,'Data Fields'!$B:$B,0),MATCH(J$9,'Data Fields'!$9:$9,0)),0) -> Branch Operations

Sheet EdCom
B9: No. | C9: DATA FIELD | D9: DOCUMENT | E9: Doc Ref No. | F9: GENERIC DATA CLASSIFICATION | G9: DATA CLASSIFICATION | H9: DATA SUBJECT CATEGORY | I9: PURPOSE OF COLLECTION | J9: REMARKS | K9: DOCUMENT OWNER
B10: 891 | C10: =IFERROR(INDEX('Data Fields'!$B:$K,MATCH($B10,'Data Fields'!$B:$B,0),MATCH(B$9,'Data Fields'!$9:$9,0)),0) -> Name | D10: =IFERROR(INDEX('Data Fields'!$B:$K,MATCH($B10,'Data Fields'!$B:$B,0),MATCH(C$9,'Data Fields'!$9:$9,0)),0) -> PMS Attendance Sheet | E10: =IFERROR(INDEX('Data Fields'!$B:$K,MATCH($B10,'Data Fields'!$B:$B,0),MATCH(D$9,'Data Fields'!$9:$9,0)),0) -> DI-ED-01 | F10: =IFERROR(INDEX('Data Fields'!$B:$K,MATCH($B10,'Data Fields'!$B:$B,0),MATCH(E$9,'Data Fields'!$9:$9,0)),0) -> 0 | G10: =IFERROR(INDEX('Data Fields'!$B:$K,MATCH($B10,'Data Fields'!$B:$B,0),MATCH(F$9,'Data Fields'!$9:$9,0)),0) -> Personal Information | H10: =IFERROR(INDEX('Data Fields'!$B:$K,MATCH($B10,'Data Fields'!$B:$B,0),MATCH(G$9,'Data Fields'!$9:$9,0)),0) -> Member | I10: =IFERROR(INDEX('Data Fields'!$B:$K,MATCH($B10,'Data Fields'!$B:$B,0),MATCH(H$9,'Data Fields'!$9:$9,0)),0) -> To identify attendee | J10: =IFERROR(INDEX('Data Fields'!$B:$K,MATCH($B10,'Data Fields'!$B:$B,0),MATCH(I$9,'Data Fields'!$9:$9,0)),0) -> 0 | K10: =IFERROR(INDEX('Data Fields'!$B:$K,MATCH($B10,'Data Fields'!$B:$B,0),MATCH(J$9,'Data Fields'!$9:$9,0)),0) -> Education and Training Committee
B11: 892 | C11: =IFERROR(INDEX('Data Fields'!$B:$K,MATCH($B11,'Data Fields'!$B:$B,0),MATCH(B$9,'Data Fields'!$9:$9,0)),0) -> Address | D11: =IFERROR(INDEX('Data Fields'!$B:$K,MATCH($B11,'Data Fields'!$B:$B,0),MATCH(C$9,'Data Fields'!$9:$9,0)),0) -> PMS Attendance Sheet | E11: =IFERROR(INDEX('Data Fields'!$B:$K,MATCH($B11,'Data Fields'!$B:$B,0),MATCH(D$9,'Data Fields'!$9:$9,0)),0) -> DI-ED-01 | F11: =IFERROR(INDEX('Data Fields'!$B:$K,MATCH($B11,'Data Fields'!$B:$B,0),MATCH(E$9,'Data Fields'!$9:$9,0)),0) -> 0 | G11: =IFERROR(INDEX('Data Fields'!$B:$K,MATCH($B11,'Data Fields'!$B:$B,0),MATCH(F$9,'Data Fields'!$9:$9,0)),0) -> Personal Information | H11: =IFERROR(INDEX('Data Fields'!$B:$K,MATCH($B11,'Data Fields'!$B:$B,0),MATCH(G$9,'Data Fields'!$9:$9,0)),0) -> Member | I11: =IFERROR(INDEX('Data Fields'!$B:$K,MATCH($B11,'Data Fields'!$B:$B,0),MATCH(H$9,'Data Fields'!$9:$9,0)),0) -> To identify attendee | J11: =IFERROR(INDEX('Data Fields'!$B:$K,MATCH($B11,'Data Fields'!$B:$B,0),MATCH(I$9,'Data Fields'!$9:$9,0)),0) -> 0 | K11: =IFERROR(INDEX('Data Fields'!$B:$K,MATCH($B11,'Data Fields'!$B:$B,0),MATCH(J$9,'Data Fields'!$9:$9,0)),0) -> Education and Training Committee
B12: 893 | C12: =IFERROR(INDEX('Data Fields'!$B:$K,MATCH($B12,'Data Fields'!$B:$B,0),MATCH(B$9,'Data Fields'!$9:$9,0)),0) -> Age (Immediate Family Member) | D12: =IFERROR(INDEX('Data Fields'!$B:$K,MATCH($B12,'Data Fields'!$B:$B,0),MATCH(C$9,'Data Fields'!$9:$9,0)),0) -> PMS Attendance Sheet | E12: =IFERROR(INDEX('Data Fields'!$B:$K,MATCH($B12,'Data Fields'!$B:$B,0),MATCH(D$9,'Data Fields'!$9:$9,0)),0) -> DI-ED-01 | F12: =IFERROR(INDEX('Data Fields'!$B:$K,MATCH($B12,'Data Fields'!$B:$B,0),MATCH(E$9,'Data Fields'!$9:$9,0)),0) -> 0 | G12: =IFERROR(INDEX('Data Fields'!$B:$K,MATCH($B12,'Data Fields'!$B:$B,0),MATCH(F$9,'Data Fields'!$9:$9,0)),0) -> Personal Information | H12: =IFERROR(INDEX('Data Fields'!$B:$K,MATCH($B12,'Data Fields'!$B:$B,0),MATCH(G$9,'Data Fields'!$9:$9,0)),0) -> Member | I12: =IFERROR(INDEX('Data Fields'!$B:$K,MATCH($B12,'Data Fields'!$B:$B,0),MATCH(H$9,'Data Fields'!$9:$9,0)),0) -> To identify attendee | J12: =IFERROR(INDEX('Data Fields'!$B:$K,MATCH($B12,'Data Fields'!$B:$B,0),MATCH(I$9,'Data Fields'!$9:$9,0)),0) -> 0 | K12: =IFERROR(INDEX('Data Fields'!$B:$K,MATCH($B12,'Data Fields'!$B:$B,0),MATCH(J$9,'Data Fields'!$9:$9,0)),0) -> Education and Training Committee
B13: 894 | C13: =IFERROR(INDEX('Data Fields'!$B:$K,MATCH($B13,'Data Fields'!$B:$B,0),MATCH(B$9,'Data Fields'!$9:$9,0)),0) -> Contact No. | D13: =IFERROR(INDEX('Data Fields'!$B:$K,MATCH($B13,'Data Fields'!$B:$B,0),MATCH(C$9,'Data Fields'!$9:$9,0)),0) -> PMS Attendance Sheet | E13: =IFERROR(INDEX('Data Fields'!$B:$K,MATCH($B13,'Data Fields'!$B:$B,0),MATCH(D$9,'Data Fields'!$9:$9,0)),0) -> DI-ED-01 | F13: =IFERROR(INDEX('Data Fields'!$B:$K,MATCH($B13,'Data Fields'!$B:$B,0),MATCH(E$9,'Data Fields'!$9:$9,0)),0) -> 0 | G13: =IFERROR(INDEX('Data Fields'!$B:$K,MATCH($B13,'Data Fields'!$B:$B,0),MATCH(F$9,'Data Fields'!$9:$9,0)),0) -> Sensitive Personal Information | H13: =IFERROR(INDEX('Data Fields'!$B:$K,MATCH($B13,'Data Fields'!$B:$B,0),MATCH(G$9,'Data Fields'!$9:$9,0)),0) -> Member | I13: =IFERROR(INDEX('Data Fields'!$B:$K,MATCH($B13,'Data Fields'!$B:$B,0),MATCH(H$9,'Data Fields'!$9:$9,0)),0) -> To contact attendee | J13: =IFERROR(INDEX('Data Fields'!$B:$K,MATCH($B13,'Data Fields'!$B:$B,0),MATCH(I$9,'Data Fields'!$9:$9,0)),0) -> 0 | K13: =IFERROR(INDEX('Data Fields'!$B:$K,MATCH($B13,'Data Fields'!$B:$B,0),MATCH(J$9,'Data Fields'!$9:$9,0)),0) -> Education and Training Committee
B14: 895 | C14: =IFERROR(INDEX('Data Fields'!$B:$K,MATCH($B14,'Data Fields'!$B:$B,0),MATCH(B$9,'Data Fields'!$9:$9,0)),0) -> Occupation | D14: =IFERROR(INDEX('Data Fields'!$B:$K,MATCH($B14,'Data Fields'!$B:$B,0),MATCH(C$9,'Data Fields'!$9:$9,0)),0) -> PMS Attendance Sheet | E14: =IFERROR(INDEX('Data Fields'!$B:$K,MATCH($B14,'Data Fields'!$B:$B,0),MATCH(D$9,'Data Fields'!$9:$9,0)),0) -> DI-ED-01 | F14: =IFERROR(INDEX('Data Fields'!$B:$K,MATCH($B14,'Data Fields'!$B:$B,0),MATCH(E$9,'Data Fields'!$9:$9,0)),0) -> 0 | G14: =IFERROR(INDEX('Data Fields'!$B:$K,MATCH($B14,'Data Fields'!$B:$B,0),MATCH(F$9,'Data Fields'!$9:$9,0)),0) -> Sensitive Personal Information | H14: =IFERROR(INDEX('Data Fields'!$B:$K,MATCH($B14,'Data Fields'!$B:$B,0),MATCH(G$9,'Data Fields'!$9:$9,0)),0) -> Member | I14: =IFERROR(INDEX('Data Fields'!$B:$K,MATCH($B14,'Data Fields'!$B:$B,0),MATCH(H$9,'Data Fields'!$9:$9,0)),0) -> To determine attendance of PMS | J14: =IFERROR(INDEX('Data Fields'!$B:$K,MATCH($B14,'Data Fields'!$B:$B,0),MATCH(I$9,'Data Fields'!$9:$9,0)),0) -> 0 | K14: =IFERROR(INDEX('Data Fields'!$B:$K,MATCH($B14,'Data Fields'!$B:$B,0),MATCH(J$9,'Data Fields'!$9:$9,0)),0) -> Education and Training Committee
B15: 896 | C15: =IFERROR(INDEX('Data Fields'!$B:$K,MATCH($B15,'Data Fields'!$B:$B,0),MATCH(B$9,'Data Fields'!$9:$9,0)),0) -> Civil Status | D15: =IFERROR(INDEX('Data Fields'!$B:$K,MATCH($B15,'Data Fields'!$B:$B,0),MATCH(C$9,'Data Fields'!$9:$9,0)),0) -> PMS Attendance Sheet | E15: =IFERROR(INDEX('Data Fields'!$B:$K,MATCH($B15,'Data Fields'!$B:$B,0),MATCH(D$9,'Data Fields'!$9:$9,0)),0) -> DI-ED-01 | F15: =IFERROR(INDEX('Data Fields'!$B:$K,MATCH($B15,'Data Fields'!$B:$B,0),MATCH(E$9,'Data Fields'!$9:$9,0)),0) -> 0 | G15: =IFERROR(INDEX('Data Fields'!$B:$K,MATCH($B15,'Data Fields'!$B:$B,0),MATCH(F$9,'Data Fields'!$9:$9,0)),0) -> Sensitive Personal Information | H15: =IFERROR(INDEX('Data Fields'!$B:$K,MATCH($B15,'Data Fields'!$B:$B,0),MATCH(G$9,'Data Fields'!$9:$9,0)),0) -> Member | I15: =IFERROR(INDEX('Data Fields'!$B:$K,MATCH($B15,'Data Fields'!$B:$B,0),MATCH(H$9,'Data Fields'!$9:$9,0)),0) -> To determine attendance of PMS | J15: =IFERROR(INDEX('Data Fields'!$B:$K,MATCH($B15,'Data Fields'!$B:$B,0),MATCH(I$9,'Data Fields'!$9:$9,0)),0) -> 0 | K15: =IFERROR(INDEX('Data Fields'!$B:$K,MATCH($B15,'Data Fields'!$B:$B,0),MATCH(J$9,'Data Fields'!$9:$9,0)),0) -> Education and Training Committee
B16: 897 | C16: =IFERROR(INDEX('Data Fields'!$B:$K,MATCH($B16,'Data Fields'!$B:$B,0),MATCH(B$9,'Data Fields'!$9:$9,0)),0) -> Member's Name | D16: =IFERROR(INDEX('Data Fields'!$B:$K,MATCH($B16,'Data Fields'!$B:$B,0),MATCH(C$9,'Data Fields'!$9:$9,0)),0) -> Loan Briefing Attendance Sheet | E16: =IFERROR(INDEX('Data Fields'!$B:$K,MATCH($B16,'Data Fields'!$B:$B,0),MATCH(D$9,'Data Fields'!$9:$9,0)),0) -> DI-ED-02 | F16: =IFERROR(INDEX('Data Fields'!$B:$K,MATCH($B16,'Data Fields'!$B:$B,0),MATCH(E$9,'Data Fields'!$9:$9,0)),0) -> 0 | G16: =IFERROR(INDEX('Data Fields'!$B:$K,MATCH($B16,'Data Fields'!$B:$B,0),MATCH(F$9,'Data Fields'!$9:$9,0)),0) -> Personal Information | H16: =IFERROR(INDEX('Data Fields'!$B:$K,MATCH($B16,'Data Fields'!$B:$B,0),MATCH(G$9,'Data Fields'!$9:$9,0)),0) -> Member | I16: =IFERROR(INDEX('Data Fields'!$B:$K,MATCH($B16,'Data Fields'!$B:$B,0),MATCH(H$9,'Data Fields'!$9:$9,0)),0) -> To determine attendance of Loan Briefing | J16: =IFERROR(INDEX('Data Fields'!$B:$K,MATCH($B16,'Data Fields'!$B:$B,0),MATCH(I$9,'Data Fields'!$9:$9,0)),0) -> 0 | K16: =IFERROR(INDEX('Data Fields'!$B:$K,MATCH($B16,'Data Fields'!$B:$B,0),MATCH(J$9,'Data Fields'!$9:$9,0)),0) -> Education and Training Committee
B17: 898 | C17: =IFERROR(INDEX('Data Fields'!$B:$K,MATCH($B17,'Data Fields'!$B:$B,0),MATCH(B$9,'Data Fields'!$9:$9,0)),0) -> Contact No. | D17: =IFERROR(INDEX('Data Fields'!$B:$K,MATCH($B17,'Data Fields'!$B:$B,0),MATCH(C$9,'Data Fields'!$9:$9,0)),0) -> Loan Briefing Attendance Sheet | E17: =IFERROR(INDEX('Data Fields'!$B:$K,MATCH($B17,'Data Fields'!$B:$B,0),MATCH(D$9,'Data Fields'!$9:$9,0)),0) -> DI-ED-02 | F17: =IFERROR(INDEX('Data Fields'!$B:$K,MATCH($B17,'Data Fields'!$B:$B,0),MATCH(E$9,'Data Fields'!$9:$9,0)),0) -> 0 | G17: =IFERROR(INDEX('Data Fields'!$B:$K,MATCH($B17,'Data Fields'!$B:$B,0),MATCH(F$9,'Data Fields'!$9:$9,0)),0) -> Personal Information | H17: =IFERROR(INDEX('Data Fields'!$B:$K,MATCH($B17,'Data Fields'!$B:$B,0),MATCH(G$9,'Data Fields'!$9:$9,0)),0) -> Member | I17: =IFERROR(INDEX('Data Fields'!$B:$K,MATCH($B17,'Data Fields'!$B:$B,0),MATCH(H$9,'Data Fields'!$9:$9,0)),0) -> To determine attendance of Loan Briefing | J17: =IFERROR(INDEX('Data Fields'!$B:$K,MATCH($B17,'Data Fields'!$B:$B,0),MATCH(I$9,'Data Fields'!$9:$9,0)),0) -> 0 | K17: =IFERROR(INDEX('Data Fields'!$B:$K,MATCH($B17,'Data Fields'!$B:$B,0),MATCH(J$9,'Data Fields'!$9:$9,0)),0) -> Education and Training Committee
B18: 899 | C18: =IFERROR(INDEX('Data Fields'!$B:$K,MATCH($B18,'Data Fields'!$B:$B,0),MATCH(B$9,'Data Fields'!$9:$9,0)),0) -> Signature | D18: =IFERROR(INDEX('Data Fields'!$B:$K,MATCH($B18,'Data Fields'!$B:$B,0),MATCH(C$9,'Data Fields'!$9:$9,0)),0) -> Loan Briefing Attendance Sheet | E18: =IFERROR(INDEX('Data Fields'!$B:$K,MATCH($B18,'Data Fields'!$B:$B,0),MATCH(D$9,'Data Fields'!$9:$9,0)),0) -> DI-ED-02 | F18: =IFERROR(INDEX('Data Fields'!$B:$K,MATCH($B18,'Data Fields'!$B:$B,0),MATCH(E$9,'Data Fields'!$9:$9,0)),0) -> 0 | G18: =IFERROR(INDEX('Data Fields'!$B:$K,MATCH($B18,'Data Fields'!$B:$B,0),MATCH(F$9,'Data Fields'!$9:$9,0)),0) -> Sensitive Personal Information | H18: =IFERROR(INDEX('Data Fields'!$B:$K,MATCH($B18,'Data Fields'!$B:$B,0),MATCH(G$9,'Data Fields'!$9:$9,0)),0) -> Member | I18: =IFERROR(INDEX('Data Fields'!$B:$K,MATCH($B18,'Data Fields'!$B:$B,0),MATCH(H$9,'Data Fields'!$9:$9,0)),0) -> To determine attendance of Loan Briefing | J18: =IFERROR(INDEX('Data Fields'!$B:$K,MATCH($B18,'Data Fields'!$B:$B,0),MATCH(I$9,'Data Fields'!$9:$9,0)),0) -> 0 | K18: =IFERROR(INDEX('Data Fields'!$B:$K,MATCH($B18,'Data Fields'!$B:$B,0),MATCH(J$9,'Data Fields'!$9:$9,0)),0) -> Education and Training Committee
B19: 900 | C19: =IFERROR(INDEX('Data Fields'!$B:$K,MATCH($B19,'Data Fields'!$B:$B,0),MATCH(B$9,'Data Fields'!$9:$9,0)),0) -> Date | D19: =IFERROR(INDEX('Data Fields'!$B:$K,MATCH($B19,'Data Fields'!$B:$B,0),MATCH(C$9,'Data Fields'!$9:$9,0)),0) -> EdCom Volunteer's Profile | E19: =IFERROR(INDEX('Data Fields'!$B:$K,MATCH($B19,'Data Fields'!$B:$B,0),MATCH(D$9,'Data Fields'!$9:$9,0)),0) -> DI-ED-03 | F19: =IFERROR(INDEX('Data Fields'!$B:$K,MATCH($B19,'Data Fields'!$B:$B,0),MATCH(E$9,'Data Fields'!$9:$9,0)),0) -> 0 | G19: =IFERROR(INDEX('Data Fields'!$B:$K,MATCH($B19,'Data Fields'!$B:$B,0),MATCH(F$9,'Data Fields'!$9:$9,0)),0) -> Non-personal Information | H19: =IFERROR(INDEX('Data Fields'!$B:$K,MATCH($B19,'Data Fields'!$B:$B,0),MATCH(G$9,'Data Fields'!$9:$9,0)),0) -> Volunteer | I19: =IFERROR(INDEX('Data Fields'!$B:$K,MATCH($B19,'Data Fields'!$B:$B,0),MATCH(H$9,'Data Fields'!$9:$9,0)),0) -> To determine date of application | J19: =IFERROR(INDEX('Data Fields'!$B:$K,MATCH($B19,'Data Fields'!$B:$B,0),MATCH(I$9,'Data Fields'!$9:$9,0)),0) -> 0 | K19: =IFERROR(INDEX('Data Fields'!$B:$K,MATCH($B19,'Data Fields'!$B:$B,0),MATCH(J$9,'Data Fields'!$9:$9,0)),0) -> Education and Training Committee
B20: 901 | C20: =IFERROR(INDEX('Data Fields'!$B:$K,MATCH($B20,'Data Fields'!$B:$B,0),MATCH(B$9,'Data Fields'!$9:$9,0)),0) -> 2x2 Picture | D20: =IFERROR(INDEX('Data Fields'!$B:$K,MATCH($B20,'Data Fields'!$B:$B,0),MATCH(C$9,'Data Fields'!$9:$9,0)),0) -> EdCom Volunteer's Profile | E20: =IFERROR(INDEX('Data Fields'!$B:$K,MATCH($B20,'Data Fields'!$B:$B,0),MATCH(D$9,'Data Fields'!$9:$9,0)),0) -> DI-ED-03 | F20: =IFERROR(INDEX('Data Fields'!$B:$K,MATCH($B20,'Data Fields'!$B:$B,0),MATCH(E$9,'Data Fields'!$9:$9,0)),0) -> 0 | G20: =IFERROR(INDEX('Data Fields'!$B:$K,MATCH($B20,'Data Fields'!$B:$B,0),MATCH(F$9,'Data Fields'!$9:$9,0)),0) -> Sensitive Personal Information | H20: =IFERROR(INDEX('Data Fields'!$B:$K,MATCH($B20,'Data Fields'!$B:$B,0),MATCH(G$9,'Data Fields'!$9:$9,0)),0) -> Volunteer | I20: =IFERROR(INDEX('Data Fields'!$B:$K,MATCH($B20,'Data Fields'!$B:$B,0),MATCH(H$9,'Data Fields'!$9:$9,0)),0) -> To determine identity of volunteer | J20: =IFERROR(INDEX('Data Fields'!$B:$K,MATCH($B20,'Data Fields'!$B:$B,0),MATCH(I$9,'Data Fields'!$9:$9,0)),0) -> 0 | K20: =IFERROR(INDEX('Data Fields'!$B:$K,MATCH($B20,'Data Fields'!$B:$B,0),MATCH(J$9,'Data Fields'!$9:$9,0)),0) -> Education and Training Committee
B21: 902 | C21: =IFERROR(INDEX('Data Fields'!$B:$K,MATCH($B21,'Data Fields'!$B:$B,0),MATCH(B$9,'Data Fields'!$9:$9,0)),0) -> Date of TOT | D21: =IFERROR(INDEX('Data Fields'!$B:$K,MATCH($B21,'Data Fields'!$B:$B,0),MATCH(C$9,'Data Fields'!$9:$9,0)),0) -> EdCom Volunteer's Profile | E21: =IFERROR(INDEX('Data Fields'!$B:$K,MATCH($B21,'Data Fields'!$B:$B,0),MATCH(D$9,'Data Fields'!$9:$9,0)),0) -> DI-ED-03 | F21: =IFERROR(INDEX('Data Fields'!$B:$K,MATCH($B21,'Data Fields'!$B:$B,0),MATCH(E$9,'Data Fields'!$9:$9,0)),0) -> 0 | G21: =IFERROR(INDEX('Data Fields'!$B:$K,MATCH($B21,'Data Fields'!$B:$B,0),MATCH(F$9,'Data Fields'!$9:$9,0)),0) -> Non-personal Information | H21: =IFERROR(INDEX('Data Fields'!$B:$K,MATCH($B21,'Data Fields'!$B:$B,0),MATCH(G$9,'Data Fields'!$9:$9,0)),0) -> Volunteer | I21: =IFERROR(INDEX('Data Fields'!$B:$K,MATCH($B21,'Data Fields'!$B:$B,0),MATCH(H$9,'Data Fields'!$9:$9,0)),0) -> To determine TOT of volunteer | J21: =IFERROR(INDEX('Data Fields'!$B:$K,MATCH($B21,'Data Fields'!$B:$B,0),MATCH(I$9,'Data Fields'!$9:$9,0)),0) -> 0 | K21: =IFERROR(INDEX('Data Fields'!$B:$K,MATCH($B21,'Data Fields'!$B:$B,0),MATCH(J$9,'Data Fields'!$9:$9,0)),0) -> Education and Training Committee
... B152: 1033 | C152: =IFERROR(INDEX('Data Fields'!$B:$K,MATCH($B152,'Data Fields'!$B:$B,0),MATCH(B$9,'Data Fields'!$9:$9,0)),0) -> Number of Accounts | D152: =IFERROR(INDEX('Data Fields'!$B:$K,MATCH($B152,'Data Fields'!$B:$B,0),MATCH(C$9,'Data Fields'!$9:$9,0)),0) -> Reason/Cause Resulting to Withdrawal of Membership | E152: =IFERROR(INDEX('Data Fields'!$B:$K,MATCH($B152,'Data Fields'!$B:$B,0),MATCH(D$9,'Data Fields'!$9:$9,0)),0) -> DI-ED-07 | F152: =IFERROR(INDEX('Data Fields'!$B:$K,MATCH($B152,'Data Fields'!$B:$B,0),MATCH(E$9,'Data Fields'!$9:$9,0)),0) -> 0 | G152: =IFERROR(INDEX('Data Fields'!$B:$K,MATCH($B152,'Data Fields'!$B:$B,0),MATCH(F$9,'Data Fields'!$9:$9,0)),0) -> Sensitive Personal Information | H152: =IFERROR(INDEX('Data Fields'!$B:$K,MATCH($B152,'Data Fields'!$B:$B,0),MATCH(G$9,'Data Fields'!$9:$9,0)),0) -> Member | I152: =IFERROR(INDEX('Data Fields'!$B:$K,MATCH($B152,'Data Fields'!$B:$B,0),MATCH(H$9,'Data Fields'!$9:$9,0)),0) -> To summarize data for report to Board of Directors | J152: =IFERROR(INDEX('Data Fields'!$B:$K,MATCH($B152,'Data Fields'!$B:$B,0),MATCH(I$9,'Data Fields'!$9:$9,0)),0) -> 0 | K152: =IFERROR(INDEX('Data Fields'!$B:$K,MATCH($B152,'Data Fields'!$B:$B,0),MATCH(J$9,'Data Fields'!$9:$9,0)),0) -> Education and Training Committee

Sheet Finance
B9: No. | C9: No.2 | D9: DATA FIELD | E9: DOCUMENT | F9: Doc Ref No. | G9: GENERIC DATA CLASSIFICATION | H9: DATA CLASSIFICATION | I9: DATA SUBJECT CATEGORY | J9: PURPOSE OF COLLECTION | K9: REMARKS | L9: DOCUMENT OWNER
B10: 1034 | C10: 1 | D10: =IFERROR(INDEX('Data Fields'!$B:$K,MATCH($B10,'Data Fields'!$B:$B,0),MATCH(B$9,'Data Fields'!$9:$9,0)),0) -> Date | E10: =IFERROR(INDEX('Data Fields'!$B:$K,MATCH($B10,'Data Fields'!$B:$B,0),MATCH(D$9,'Data Fields'!$9:$9,0)),0) -> Requisition Slip | F10: =IFERROR(INDEX('Data Fields'!$B:$K,MATCH($B10,'Data Fields'!$B:$B,0),MATCH(E$9,'Data Fields'!$9:$9,0)),0) -> DI-FD-01 | G10: =IFERROR(INDEX('Data Fields'!$B:$K,MATCH($B10,'Data Fields'!$B:$B,0),MATCH(F$9,'Data Fields'!$9:$9,0)),0) -> 0 | H10: =IFERROR(INDEX('Data Fields'!$B:$K,MATCH($B10,'Data Fields'!$B:$B,0),MATCH(G$9,'Data Fields'!$9:$9,0)),0) -> Non-personal Information | I10: =IFERROR(INDEX('Data Fields'!$B:$K,MATCH($B10,'Data Fields'!$B:$B,0),MATCH(H$9,'Data Fields'!$9:$9,0)),0) -> Employee | J10: =IFERROR(INDEX('Data Fields'!$B:$K,MATCH($B10,'Data Fields'!$B:$B,0),MATCH(I$9,'Data Fields'!$9:$9,0)),0) -> To determine the date of the request | K10: =IFERROR(INDEX('Data Fields'!$B:$K,MATCH($B10,'Data Fields'!$B:$B,0),MATCH(J$9,'Data Fields'!$9:$9,0)),0) -> 0 | L10: =IFERROR(INDEX('Data Fields'!$B:$K,MATCH($B10,'Data Fields'!$B:$B,0),MATCH(K$9,'Data Fields'!$9:$9,0)),0) -> Finance Department
B11: 1035 | C11: 2 | D11: =IFERROR(INDEX('Data Fields'!$B:$K,MATCH($B11,'Data Fields'!$B:$B,0),MATCH(B$9,'Data Fields'!$9:$9,0)),0) -> Quantity | E11: =IFERROR(INDEX('Data Fields'!$B:$K,MATCH($B11,'Data Fields'!$B:$B,0),MATCH(D$9,'Data Fields'!$9:$9,0)),0) -> Requisition Slip | F11: =IFERROR(INDEX('Data Fields'!$B:$K,MATCH($B11,'Data Fields'!$B:$B,0),MATCH(E$9,'Data Fields'!$9:$9,0)),0) -> DI-FD-01 | G11: =IFERROR(INDEX('Data Fields'!$B:$K,MATCH($B11,'Data Fields'!$B:$B,0),MATCH(F$9,'Data Fields'!$9:$9,0)),0) -> 0 | H11: =IFERROR(INDEX('Data Fields'!$B:$K,MATCH($B11,'Data Fields'!$B:$B,0),MATCH(G$9,'Data Fields'!$9:$9,0)),0) -> Non-personal Information | I11: =IFERROR(INDEX('Data Fields'!$B:$K,MATCH($B11,'Data Fields'!$B:$B,0),MATCH(H$9,'Data Fields'!$9:$9,0)),0) -> Employee | J11: =IFERROR(INDEX('Data Fields'!$B:$K,MATCH($B11,'Data Fields'!$B:$B,0),MATCH(I$9,'Data Fields'!$9:$9,0)),0) -> To determine the quantity of materials to be acquired | K11: =IFERROR(INDEX('Data Fields'!$B:$K,MATCH($B11,'Data Fields'!$B:$B,0),MATCH(J$9,'Data Fields'!$9:$9,0)),0) -> 0 | L11: =IFERROR(INDEX('Data Fields'!$B:$K,MATCH($B11,'Data Fields'!$B:$B,0),MATCH(K$9,'Data Fields'!$9:$9,0)),0) -> Finance Department
B12: 1036 | C12: 3 | D12: =IFERROR(INDEX('Data Fields'!$B:$K,MATCH($B12,'Data Fields'!$B:$B,0),MATCH(B$9,'Data Fields'!$9:$9,0)),0) -> Unit | E12: =IFERROR(INDEX('Data Fields'!$B:$K,MATCH($B12,'Data Fields'!$B:$B,0),MATCH(D$9,'Data Fields'!$9:$9,0)),0) -> Requisition Slip | F12: =IFERROR(INDEX('Data Fields'!$B:$K,MATCH($B12,'Data Fields'!$B:$B,0),MATCH(E$9,'Data Fields'!$9:$9,0)),0) -> DI-FD-01 | G12: =IFERROR(INDEX('Data Fields'!$B:$K,MATCH($B12,'Data Fields'!$B:$B,0),MATCH(F$9,'Data Fields'!$9:$9,0)),0) -> 0 | H12: =IFERROR(INDEX('Data Fields'!$B:$K,MATCH($B12,'Data Fields'!$B:$B,0),MATCH(G$9,'Data Fields'!$9:$9,0)),0) -> Non-personal Information | I12: =IFERROR(INDEX('Data Fields'!$B:$K,MATCH($B12,'Data Fields'!$B:$B,0),MATCH(H$9,'Data Fields'!$9:$9,0)),0) -> Employee | J12: =IFERROR(INDEX('Data Fields'!$B:$K,MATCH($B12,'Data Fields'!$B:$B,0),MATCH(I$9,'Data Fields'!$9:$9,0)),0) -> To determine the unit quantity of materials to be acquired | K12: =IFERROR(INDEX('Data Fields'!$B:$K,MATCH($B12,'Data Fields'!$B:$B,0),MATCH(J$9,'Data Fields'!$9:$9,0)),0) -> 0 | L12: =IFERROR(INDEX('Data Fields'!$B:$K,MATCH($B12,'Data Fields'!$B:$B,0),MATCH(K$9,'Data Fields'!$9:$9,0)),0) -> Finance Department
B13: 1037 | C13: 4 | D13: =IFERROR(INDEX('Data Fields'!$B:$K,MATCH($B13,'Data Fields'!$B:$B,0),MATCH(B$9,'Data Fields'!$9:$9,0)),0) -> Description | E13: =IFERROR(INDEX('Data Fields'!$B:$K,MATCH($B13,'Data Fields'!$B:$B,0),MATCH(D$9,'Data Fields'!$9:$9,0)),0) -> Requisition Slip | F13: =IFERROR(INDEX('Data Fields'!$B:$K,MATCH($B13,'Data Fields'!$B:$B,0),MATCH(E$9,'Data Fields'!$9:$9,0)),0) -> DI-FD-01 | G13: =IFERROR(INDEX('Data Fields'!$B:$K,MATCH($B13,'Data Fields'!$B:$B,0),MATCH(F$9,'Data Fields'!$9:$9,0)),0) -> 0 | H13: =IFERROR(INDEX('Data Fields'!$B:$K,MATCH($B13,'Data Fields'!$B:$B,0),MATCH(G$9,'Data Fields'!$9:$9,0)),0) -> Non-personal Information | I13: =IFERROR(INDEX('Data Fields'!$B:$K,MATCH($B13,'Data Fields'!$B:$B,0),MATCH(H$9,'Data Fields'!$9:$9,0)),0) -> Employee | J13: =IFERROR(INDEX('Data Fields'!$B:$K,MATCH($B13,'Data Fields'!$B:$B,0),MATCH(I$9,'Data Fields'!$9:$9,0)),0) -> To determine the description of materials to be acquired | K13: =IFERROR(INDEX('Data Fields'!$B:$K,MATCH($B13,'Data Fields'!$B:$B,0),MATCH(J$9,'Data Fields'!$9:$9,0)),0) -> 0 | L13: =IFERROR(INDEX('Data Fields'!$B:$K,MATCH($B13,'Data Fields'!$B:$B,0),MATCH(K$9,'Data Fields'!$9:$9,0)),0) -> Finance Department
